Workbook

Sheet Read me
A1: Design-Build-Fly inventory (DBF-INV-001)
A2: Owner: Tristan Hottier, Inventory Czar. Lift + cruise VTOL, design revision 0.3.1.
A4: How to use
A5: Inventory tab: one row per stock line. P- rows are bought, M- rows are made in-house, N- rows are the proposed Nautical Wings carbon props.
A6: Edit only the blue cells: Qty ordered, Qty on hand, Status, Location, Order date, Received date, Inspected, Actual USD, Notes.
A7: Black cells are formulas (Ext USD, Qty still to get). Status and Inspected use dropdowns; status colours update by themselves.
A8: When a delivery arrives: count it against the packing slip, set Qty on hand, Received date and Inspected, label the item with its ID and put it in its kit bin (K1 to K7).
A9: Budget tab: totals against the $2,000 cap, the crash reserve, spend by kit and the effect of the Nautical Wings prop swap.
A11: Where the numbers come from
A12: Rows were generated on 2026-10-19 from docs/purchasing/C0_BOM.csv (prices checked 2026-10-13) and the CAD assembly in cad/params.txt, by inventory/build_inventory.mjs in the DBF-VTOL repo.
A13: Nothing has been ordered or built yet, so every on-hand quantity starts at 0. Re-check prices before ordering.
A14: Overview page: Inventory-Overview.html in the DBF-VTOL repo.

Sheet Budget
A1: Budget against the $2,000 cap
A2: Blue cells are inputs; black cells are formulas over the Inventory tab.
A3: Inputs
A4: Hardware budget cap | B4: 2000 | C4: Source: docs/DESIGN-BASIS.md R6 (fixed, includes tax and shipping)
A5: Sales/use tax rate (Berkeley) | B5: 0.1025 | C5: Source: C0_BOM.csv, CDTFA rate 2026-10-01
A6: Shipping allowance (estimate) | B6: 100 | C6: Source: C0_BOM.csv; estimate, price at checkout
A8: Plan (BOM prices)
A9: Goods subtotal (Buy lines) | B9: =SUMIFS(Inventory!$N$2:$N$500,Inventory!$C$2:$C$500,"Buy")
A10: Sales/use tax | B10: =B9*B5
A11: Shipping allowance | B11: =B6
A12: Committed spend | B12: =B9+B10+B11
A13: Crash reserve left under the cap | B13: =B4-B12
A14: Reserve check: BOM says $102.08 | B14: =IF(ROUND(B13,1)=102.1,"matches C0_BOM.csv","differs from C0_BOM.csv: re-check")
A16: Actual spend (fill Actual USD on the Inventory tab, tax and shipping included)
A17: Spent so far | B17: =SUM(Inventory!$O$2:$O$500)
A18: Left under the cap | B18: =B4-B17
A20: Nautical Wings carbon props (proposed, free)
A21: Retail prop lines on hold (goods) | B21: =SUMIFS(Inventory!$N$2:$N$500,Inventory!$K$2:$K$500,"Hold*")
A22: Same with tax | B22: =B21*(1+B5)
A23: Reserve if the NWA props are confirmed (EST) | B23: =B13+B22 | C23: EST: assumes the props are free with no shipping or import cost; shipping allowance unchanged
A25: By kit
A26: Kit | B26: Name | C26: Lines | D26: Still to get (lines) | E26: Plan goods (USD)
A27: =Lists!B2 | B27: =Lists!C2 | C27: =COUNTIFS(Inventory!$E$2:$E$500,A27) | D27: =COUNTIFS(Inventory!$E$2:$E$500,A27,Inventory!$J$2:$J$500,">0") | E27: =SUMIFS(Inventory!$N$2:$N$500,Inventory!$E$2:$E$500,A27,Inventory!$C$2:$C$500,"Buy")
A28: =Lists!B3 | B28: =Lists!C3 | C28: =COUNTIFS(Inventory!$E$2:$E$500,A28) | D28: =COUNTIFS(Inventory!$E$2:$E$500,A28,Inventory!$J$2:$J$500,">0") | E28: =SUMIFS(Inventory!$N$2:$N$500,Inventory!$E$2:$E$500,A28,Inventory!$C$2:$C$500,"Buy")
A29: =Lists!B4 | B29: =Lists!C4 | C29: =COUNTIFS(Inventory!$E$2:$E$500,A29) | D29: =COUNTIFS(Inventory!$E$2:$E$500,A29,Inventory!$J$2:$J$500,">0") | E29: =SUMIFS(Inventory!$N$2:$N$500,Inventory!$E$2:$E$500,A29,Inventory!$C$2:$C$500,"Buy")
A30: =Lists!B5 | B30: =Lists!C5 | C30: =COUNTIFS(Inventory!$E$2:$E$500,A30) | D30: =COUNTIFS(Inventory!$E$2:$E$500,A30,Inventory!$J$2:$J$500,">0") | E30: =SUMIFS(Inventory!$N$2:$N$500,Inventory!$E$2:$E$500,A30,Inventory!$C$2:$C$500,"Buy")
A31: =Lists!B6 | B31: =Lists!C6 | C31: =COUNTIFS(Inventory!$E$2:$E$500,A31) | D31: =COUNTIFS(Inventory!$E$2:$E$500,A31,Inventory!$J$2:$J$500,">0") | E31: =SUMIFS(Inventory!$N$2:$N$500,Inventory!$E$2:$E$500,A31,Inventory!$C$2:$C$500,"Buy")
A32: =Lists!B7 | B32: =Lists!C7 | C32: =COUNTIFS(Inventory!$E$2:$E$500,A32) | D32: =COUNTIFS(Inventory!$E$2:$E$500,A32,Inventory!$J$2:$J$500,">0") | E32: =SUMIFS(Inventory!$N$2:$N$500,Inventory!$E$2:$E$500,A32,Inventory!$C$2:$C$500,"Buy")
A33: =Lists!B8 | B33: =Lists!C8 | C33: =COUNTIFS(Inventory!$E$2:$E$500,A33) | D33: =COUNTIFS(Inventory!$E$2:$E$500,A33,Inventory!$J$2:$J$500,">0") | E33: =SUMIFS(Inventory!$N$2:$N$500,Inventory!$E$2:$E$500,A33,Inventory!$C$2:$C$500,"Buy")
A34: Total | C34: =SUM(C27:C33) | D34: =SUM(D27:D33) | E34: =SUM(E27:E33)

Sheet Inventory
A1: ID | B1: Item | C1: Type | D1: Category | E1: Kit | F1: CAD part | G1: Qty needed | H1: Qty ordered | I1: Qty on hand | J1: Qty still to get | K1: Status | L1: Vendor | M1: Unit USD | N1: Ext USD | O1: Actual USD | P1: Made from | Q1: Process | R1: Location | S1: Order date | T1: Received date | U1: Inspected | V1: Source | W1: Notes
A2: P-01 | B2: Polymaker PA6-CF20 500 g (motor mounts: HDT 173 °C) | C2: Buy | D2: Airframe | E2: K7 | G2: 1 | H2: 0 | I2: 0 | J2: =MAX(0,G2-I2-N(H2)) | K2: To order | L2: — | M2: 39.99 | N2: =G2*M2 | R2: — | V2: C0_BOM.csv: AM §2d | W2: PETG too close to motor heat (sec. 12)
A3: P-02 | B3: Hot-wire bow, nichrome + bench supply (wing cores) | C3: Buy | D3: Airframe | E3: K7 | G3: 1 | H3: 0 | I3: 0 | J3: =MAX(0,G3-I3-N(H3)) | K3: To order | L3: — | M3: 40 | N3: =G3*M3 | R3: — | V3: C0_BOM.csv: EST allowance | W3: not priced; borrow if a makerspace has one
A4: P-03 | B4: Scotch heavy-duty packing tape, 6 rolls (skin) | C4: Buy | D4: Airframe | E4: K7 | G4: 1 | H4: 0 | I4: 0 | J4: =MAX(0,G4-I4-N(H4)) | K4: To order | L4: Amazon | M4: 19.98 | N4: =G4*M4 | R4: — | V4: C0_BOM.csv: BF §2 amazon.com
A5: P-04 | B5: Hardware kit: XT90S, wire, extensions, screws, inserts, horns, pushrods, hinge tape, heat shrink, UBEC, epoxy | C5: Buy | D5: Airframe | E5: K7 | G5: 1 | H5: 0 | I5: 0 | J5: =MAX(0,G5-I5-N(H5)) | K5: To order | L5: Amazon | M5: 124.01 | N5: =G5*M5 | R5: — | V5: C0_BOM.csv: BF §3 amazon.com (itemised in file)
A6: P-05 | B6: ELEGOO PETG 1 kg (clamps, pod frames, gear clamps) | C6: Buy | D6: Airframe | E6: K7 | G6: 2 | H6: 0 | I6: 0 | J6: =MAX(0,G6-I6-N(H6)) | K6: To order | L6: Amazon | M6: 12.99 | N6: =G6*M6 | R6: — | V6: C0_BOM.csv: BF §5
A7: P-06 | B7: BNTECHGO 12 AWG silicone wire, 2nd pack (ESC feeds) | C7: Buy | D7: Airframe | E7: K7 | G7: 1 | H7: 0 | I7: 0 | J7: =MAX(0,G7-I7-N(H7)) | K7: To order | L7: Amazon | M7: 14.98 | N7: =G7*M7 | R7: — | V7: C0_BOM.csv: BF §3a item 3 amazon.com
A8: P-07 | B8: 14 AWG silicone wire (pusher / BEC feeds) | C8: Buy | D8: Airframe | E8: K7 | G8: 1 | H8: 0 | I8: 0 | J8: =MAX(0,G8-I8-N(H8)) | K8: To order | L8: Amazon | M8: 9.99 | N8: =G8*M8 | R8: — | V8: C0_BOM.csv: BF §3b amazon.com
A9: P-08 | B9: XT60H connectors 12 pairs (boom harness disconnects) | C9: Buy | D9: Airframe | E9: K7 | G9: 1 | H9: 0 | I9: 0 | J9: =MAX(0,G9-I9-N(H9)) | K9: To order | L9: Amazon | M9: 6.99 | N9: =G9*M9 | R9: — | V9: C0_BOM.csv: BF §3b amazon.com
A10: P-09 | B10: 300 mm servo extension leads, 2nd pack | C10: Buy | D10: Airframe | E10: K7 | G10: 1 | H10: 0 | I10: 0 | J10: =MAX(0,G10-I10-N(H10)) | K10: To order | L10: Amazon | M10: 6.99 | N10: =G10*M10 | R10: — | V10: C0_BOM.csv: BF §3a item 4 amazon.com
A11: P-10 | B11: Foam-safe glue 4 oz | C11: Buy | D11: Airframe | E11: K7 | G11: 1 | H11: 0 | I11: 0 | J11: =MAX(0,G11-I11-N(H11)) | K11: To order | L11: Amazon | M11: 12.99 | N11: =G11*M11 | R11: — | V11: C0_BOM.csv: BF §3b amazon.com
A12: P-11 | B12: ShareGoo LiPo battery straps (10) | C12: Buy | D12: Airframe | E12: K7 | G12: 1 | H12: 0 | I12: 0 | J12: =MAX(0,G12-I12-N(H12)) | K12: To order | L12: Amazon | M12: 7.99 | N12: =G12*M12 | R12: — | V12: C0_BOM.csv: BF §3b amazon.com
A13: P-12 | B13: Ovonic 6S 6500 100C — 2-pack listing (2 packs) | C13: Buy | D13: Energy | E13: K4 | F13: Battery_6S_LiPo | G13: 1 | H13: 0 | I13: 0 | J13: =MAX(0,G13-I13-N(H13)) | K13: To order | L13: Amazon | M13: 138.99 | N13: =G13*M13 | R13: — | V13: C0_BOM.csv: BE §1 amazon.com | W13: second pack per R7; EC5 leads: re-terminate to XT90S
A14: P-13 | B14: HTRC C150 charger (150 W, ~6 A on 6S) | C14: Buy | D14: Energy | E14: K6 | G14: 1 | H14: 0 | I14: 0 | J14: =MAX(0,G14-I14-N(H14)) | K14: To order | L14: Amazon | M14: 56.99 | N14: =G14*M14 | R14: — | V14: C0_BOM.csv: BE §2 amazon.com/dp/B0H4QLJYHY
A15: P-14 | B15: JeeFly 1755 carbon prop (pair) | C15: Buy | D15: Lift propulsion | E15: K2 | F15: Lift_Prop | G15: 2 | H15: 0 | I15: 0 | J15: =MAX(0,G15-I15-N(H15)) | K15: Hold: NWA swap pending | L15: Amazon | M15: 18.6 | N15: =G15*M15 | R15: — | V15: C0_BOM.csv: BL props amazon.com/dp/B0FJ21V736 | W15: $4.99 delivery, likely CN; Retail fallback if the Nautical Wings carbon props are not confirmed
A16: P-15 | B16: SoloGood 45A ESC (4-pack) | C16: Buy | D16: Lift propulsion | E16: K2 | G16: 2 | H16: 0 | I16: 0 | J16: =MAX(0,G16-I16-N(H16)) | K16: To order | L16: Amazon | M16: 39.99 | N16: =G16*M16 | R16: — | V16: C0_BOM.csv: BL ESCs amazon.com | W16: 4 lift + pusher + 3 spare; low stock: fallback LANRC 35A
A17: P-16 | B17: JeeFly 1755 spare pair (amazon.com) | C17: Buy | D17: Spares | E17: K2 | G17: 1 | H17: 0 | I17: 0 | J17: =MAX(0,G17-I17-N(H17)) | K17: Hold: NWA swap pending | L17: Amazon | M17: 18.6 | N17: =G17*M17 | R17: — | V17: C0_BOM.csv: BL | W17: Retail fallback if the Nautical Wings carbon props are not confirmed
A18: P-17 | B18: Du-Bro 230 pushrod 5-pack (spares) | C18: Buy | D18: Spares | E18: K7 | G18: 1 | H18: 0 | I18: 0 | J18: =MAX(0,G18-I18-N(H18)) | K18: To order | L18: Amazon | M18: 12.48 | N18: =G18*M18 | R18: — | V18: C0_BOM.csv: BF §3b amazon.com
A19: P-18 | B19: Tenergy LiPo bag | C19: Buy | D19: Test & safety | E19: K6 | G19: 1 | H19: 0 | I19: 0 | J19: =MAX(0,G19-I19-N(H19)) | K19: To order | L19: Amazon | M19: 8.99 | N19: =G19*M19 | R19: — | V19: C0_BOM.csv: BE §3
A20: P-19 | B20: Watt meter 150 A / 60 V | C20: Buy | D20: Test & safety | E20: K6 | G20: 1 | H20: 0 | I20: 0 | J20: =MAX(0,G20-I20-N(H20)) | K20: To order | L20: Amazon | M20: 12.99 | N20: =G20*M20 | R20: — | V20: C0_BOM.csv: BE §3
A21: P-20 | B21: IR thermometer | C21: Buy | D21: Test & safety | E21: K6 | G21: 1 | H21: 0 | I21: 0 | J21: =MAX(0,G21-I21-N(H21)) | K21: To order | L21: Amazon | M21: 8.98 | N21: =G21*M21 | R21: — | V21: C0_BOM.csv: BE §3
A22: P-21 | B22: 20 kg load cell + HX711 kit (thrust stand) | C22: Buy | D22: Test & safety | E22: K6 | G22: 1 | H22: 0 | I22: 0 | J22: =MAX(0,G22-I22-N(H22)) | K22: To order | L22: Amazon | M22: 8.98 | N22: =G22*M22 | R22: — | V22: C0_BOM.csv: BE §4
A23: P-22 | B23: Arduino Nano clone (thrust stand) | C23: Buy | D23: Test & safety | E23: K6 | G23: 1 | H23: 0 | I23: 0 | J23: =MAX(0,G23-I23-N(H23)) | K23: To order | L23: Amazon | M23: 8.99 | N23: =G23*M23 | R23: — | V23: C0_BOM.csv: BE §4
A24: P-23 | B24: APC 14x8.5EP pusher prop | C24: Buy | D24: Cruise propulsion | E24: K4 | F24: Pusher_Prop_14in | G24: 3 | H24: 0 | I24: 0 | J24: =MAX(0,G24-I24-N(H24)) | K24: Hold: NWA swap pending | L24: APC Propellers | M24: 6.79 | N24: =G24*M24 | R24: — | V24: C0_BOM.csv: PB 1c | W24: Retail fallback if the Nautical Wings carbon props are not confirmed
A25: P-24 | B25: EMAX ES3005HV servo | C25: Buy | D25: Controls | E25: K1 | G25: 5 | H25: 0 | I25: 0 | J25: =MAX(0,G25-I25-N(H25)) | K25: To order | L25: EMAX USA | M25: 19.99 | N25: =G25*M25 | R25: — | V25: C0_BOM.csv: BA §6 shop.emax-usa.com | W25: 2 ailerons, elevator, 2 rudders
A26: P-25 | B26: EMAX ES3005HV spare servo | C26: Buy | D26: Spares | E26: K1 | G26: 1 | H26: 0 | I26: 0 | J26: =MAX(0,G26-I26-N(H26)) | K26: To order | L26: EMAX USA | M26: 19.99 | N26: =G26*M26 | R26: — | V26: C0_BOM.csv: BA §6
A27: P-26 | B27: Harbor Freight 0.50 cal ammo can (pack storage) | C27: Buy | D27: Test & safety | E27: K6 | G27: 1 | H27: 0 | I27: 0 | J27: =MAX(0,G27-I27-N(H27)) | K27: To order | L27: Harbor Freight | M27: 19.99 | N27: =G27*M27 | R27: — | V27: C0_BOM.csv: BE §3
A28: P-27 | B28: Holybro MS5525DSO + PT40 airspeed | C28: Buy | D28: Avionics | E28: K4 | F28: Pitot_Tube | G28: 1 | H28: 0 | I28: 0 | J28: =MAX(0,G28-I28-N(H28)) | K28: To order | L28: Holybro (ships CN) | M28: 59.99 | N28: =G28*M28 | R28: — | V28: C0_BOM.csv: BA §3 holybro.com | W28: ships CN
A29: P-28 | B29: FOAMULAR NGX F-250 2 in x 4 x 8 ft (wing cores) | C29: Buy | D29: Airframe | E29: K7 | G29: 1 | H29: 0 | I29: 0 | J29: =MAX(0,G29-I29-N(H29)) | K29: To order | L29: Home Depot | M29: 59.97 | N29: =G29*M29 | R29: — | V29: C0_BOM.csv: BF §2 homedepot.com
A30: P-29 | B30: FOAMULAR 150 1 in x 4 x 8 ft (tail, pod) | C30: Buy | D30: Airframe | E30: K7 | G30: 1 | H30: 0 | I30: 0 | J30: =MAX(0,G30-I30-N(H30)) | K30: To order | L30: Home Depot | M30: 30.97 | N30: =G30*M30 | R30: — | V30: C0_BOM.csv: BF §2 homedepot.com
A31: P-30 | B31: 6061-T6 tube 1.000 x 0.035 in x 72 in (booms) | C31: Buy | D31: Airframe | E31: K7 | G31: 2 | H31: 0 | I31: 0 | J31: =MAX(0,G31-I31-N(H31)) | K31: To order | L31: OnlineMetals | M31: 26.2 | N31: =G31*M31 | R31: — | V31: C0_BOM.csv: BF §1 onlinemetals.com | W31: cut list 0.955 + 0.516 + 0.955 + 0.516 m
A32: P-31 | B32: 6061-T6 tube 1.000 x 0.058 in x 96 in (spar sockets + gear legs) | C32: Buy | D32: Airframe | E32: K7 | G32: 1 | H32: 0 | I32: 0 | J32: =MAX(0,G32-I32-N(H32)) | K32: To order | L32: OnlineMetals | M32: 53.97 | N32: =G32*M32 | R32: — | V32: C0_BOM.csv: BF §1 | W32: 2 x 0.8 m sockets + 4 x 0.205 m legs + kerf
A33: P-32 | B33: 6061-T6 tube 0.875 x 0.058 in x 36 in (joiner) | C33: Buy | D33: Airframe | E33: K7 | G33: 1 | H33: 0 | I33: 0 | J33: =MAX(0,G33-I33-N(H33)) | K33: To order | L33: OnlineMetals | M33: 18.45 | N33: =G33*M33 | R33: — | V33: C0_BOM.csv: BF §1 | W33: 0.76 m joiner, 0.30 m engagement per side; 0.23 mm clearance
A34: P-33 | B34: HGLRC M100-5883 GPS + compass | C34: Buy | D34: Avionics | E34: K4 | G34: 1 | H34: 0 | I34: 0 | J34: =MAX(0,G34-I34-N(H34)) | K34: To order | L34: RaceDayQuads | M34: 20.49 | N34: =G34*M34 | R34: — | V34: C0_BOM.csv: BA §2 racedayquads.com
A35: P-34 | B35: NewBeeDrone BeeID v1.1 Remote ID (FAA DoC RID000001995) | C35: Buy | D35: Avionics | E35: K4 | G35: 1 | H35: 0 | I35: 0 | J35: =MAX(0,G35-I35-N(H35)) | K35: To order | L35: RaceDayQuads | M35: 36.99 | N35: =G35*M35 | R35: — | V35: C0_BOM.csv: BA §4 racedayquads.com
A36: P-35 | B36: RadioMaster Pocket Crush ELRS | C36: Buy | D36: Avionics | E36: K6 | G36: 1 | H36: 0 | I36: 0 | J36: =MAX(0,G36-I36-N(H36)) | K36: To order | L36: RadioMaster | M36: 64.99 | N36: =G36*M36 | R36: — | V36: C0_BOM.csv: BA §5 radiomasterrc.com
A37: P-36 | B37: RadioMaster RP3 V2 ELRS receiver | C37: Buy | D37: Avionics | E37: K4 | G37: 1 | H37: 0 | I37: 0 | J37: =MAX(0,G37-I37-N(H37)) | K37: To order | L37: RadioMaster | M37: 19.99 | N37: =G37*M37 | R37: — | V37: C0_BOM.csv: BA §5
A38: P-37 | B38: CoreWing F405 Wing APP V2 (12 out, 90 A sensor) | C38: Buy | D38: Avionics | E38: K4 | G38: 1 | H38: 0 | I38: 0 | J38: =MAX(0,G38-I38-N(H38)) | K38: To order | L38: ReadyMadeRC | M38: 67.26 | N38: =G38*M38 | R38: — | V38: C0_BOM.csv: BA §2 readymaderc.com | W38: ArduPilot target beta-only (4.7.2-beta); fallback Matek F405-WMO $69.99
A39: P-38 | B39: SunnySky X4110S 400KV (pusher) | C39: Buy | D39: Cruise propulsion | E39: K4 | F39: Pusher_Motor | G39: 1 | H39: 0 | I39: 0 | J39: =MAX(0,G39-I39-N(H39)) | K39: To order | L39: SunnySky USA | M39: 46.99 | N39: =G39*M39 | R39: — | V39: C0_BOM.csv: BL A3 | W39: same motor as lift: one spare covers both
A40: P-39 | B40: SunnySky X4110S 400KV | C40: Buy | D40: Lift propulsion | E40: K2 | F40: Lift_Motor | G40: 4 | H40: 0 | I40: 0 | J40: =MAX(0,G40-I40-N(H40)) | K40: To order | L40: SunnySky USA | M40: 46.99 | N40: =G40*M40 | R40: — | V40: C0_BOM.csv: BL A3 sunnyskyusa.com
...

Sheet Lists
A1: Status | B1: Kit | C1: Kit name | D1: Inspected | E1: Type
A2: To order | B2: K1 | C2: Wing | D2: Y | E2: Buy
A3: Ordered | B3: K2 | C3: Booms & lift | D3: N | E3: Make
A4: Received | B4: K3 | C4: Tail | D4: Partial | E4: NWA
A5: Inspected OK | B5: K4 | C5: Pod, avionics & pusher
A6: Rejected | B6: K5 | C6: Landing gear
A7: To make | B7: K6 | C7: Ground support & test
A8: In progress | B8: K7 | C8: Raw stock & consumables
A9: Made
A10: To source
A11: Hold: NWA swap pending
A12: Proposed: confirm with NWA
A13: Cancelled

Sheet Data Sources
A1: Written to | B1: Source | C1: Object | D1: Obtained via | E1: Run at
A2: Inventory!A1:W68 | B2: DBF-VTOL repo | C2: inventory/inventory.json (C0_BOM.csv + cad/params.txt) | D2: Generated by inventory/build_inventory.mjs, run by Claude | E2: 2026-10-19
